[07/Dec/2015 10:28:47] WARNING [django.request:144] Not Found: /jqueryCalendar/jquery-1.6.2.min.js
[07/Dec/2015 10:28:48] WARNING [django.request:144] Not Found: /jqueryCalendar/jqueryCalendar.css
[07/Dec/2015 10:28:49] WARNING [django.request:144] Not Found: /jqueryCalendar/jquery-ui-1.8.15.custom.min.js
[07/Dec/2015 10:34:34] WARNING [django.request:144] Not Found: /jqueryCalendar/jquery-1.6.2.min.js
[07/Dec/2015 10:34:34] WARNING [django.request:144] Not Found: /jqueryCalendar/jquery-ui-1.8.15.custom.min.js
[07/Dec/2015 10:34:34] WARNING [django.request:144] Not Found: /jqueryCalendar/jqueryCalendar.css
[07/Dec/2015 10:36:56] WARNING [django.request:144] Not Found: /jqueryCalendar/jquery-1.6.2.min.js
[07/Dec/2015 10:36:56] WARNING [django.request:144] Not Found: /jqueryCalendar/jqueryCalendar.css
[07/Dec/2015 10:36:56] WARNING [django.request:144] Not Found: /jqueryCalendar/jquery-ui-1.8.15.custom.min.js
[07/Dec/2015 10:53:53] WARNING [django.request:144] Not Found: /jqueryCalendar/jquery-ui-1.8.15.custom.min.js
[07/Dec/2015 10:53:53] WARNING [django.request:144] Not Found: /jqueryCalendar/jqueryCalendar.css
[07/Dec/2015 10:53:53] WARNING [django.request:144] Not Found: /jqueryCalendar/jquery-1.6.2.min.js
[07/Dec/2015 10:54:16] WARNING [django.request:144] Not Found: /jqueryCalendar/jquery-1.6.2.min.js
[07/Dec/2015 10:54:16] WARNING [django.request:144] Not Found: /jqueryCalendar/jquery-ui-1.8.15.custom.min.js
[07/Dec/2015 10:54:16] WARNING [django.request:144] Not Found: /jqueryCalendar/jqueryCalendar.css
[07/Dec/2015 11:03:39] ERROR [django.request:210] Internal Server Error: /
Traceback (most recent call last):
  File "/home/osboxes/.local/lib/python2.7/site-packages/django/core/handlers/base.py", line 101, in get_response
    resolver_match = resolver.resolve(request.path_info)
  File "/home/osboxes/.local/lib/python2.7/site-packages/django/core/urlresolvers.py", line 338, in resolve
    for pattern in self.url_patterns:
  File "/home/osboxes/.local/lib/python2.7/site-packages/django/core/urlresolvers.py", line 366, in url_patterns
    patterns = getattr(self.urlconf_module, "urlpatterns", self.urlconf_module)
  File "/home/osboxes/.local/lib/python2.7/site-packages/django/core/urlresolvers.py", line 361, in urlconf_module
    self._urlconf_module = import_module(self.urlconf_name)
  File "/home/osboxes/.local/lib/python2.7/site-packages/django/utils/importlib.py", line 35, in import_module
    __import__(name)
  File "/home/osboxes/Desktop/tweetone/tweetone/urls.py", line 3, in <module>
    from tweetexamp import views
  File "/home/osboxes/Desktop/tweetone/tweetexamp/views.py", line 23, in <module>
    logger = logging.getLogger(connection)
  File "/usr/lib/python2.7/logging/__init__.py", line 1572, in getLogger
    return Logger.manager.getLogger(name)
  File "/usr/lib/python2.7/logging/__init__.py", line 1036, in getLogger
    raise TypeError('A logger name must be string or Unicode')
TypeError: A logger name must be string or Unicode
[07/Dec/2015 11:04:33] WARNING [django.request:144] Not Found: /jqueryCalendar/jquery-1.6.2.min.js
[07/Dec/2015 11:04:33] WARNING [django.request:144] Not Found: /jqueryCalendar/jqueryCalendar.css
[07/Dec/2015 11:04:33] WARNING [django.request:144] Not Found: /jqueryCalendar/jquery-ui-1.8.15.custom.min.js
[07/Dec/2015 11:04:51] WARNING [django.request:144] Not Found: /jqueryCalendar/jquery-1.6.2.min.js
[07/Dec/2015 11:04:51] WARNING [django.request:144] Not Found: /jqueryCalendar/jqueryCalendar.css
[07/Dec/2015 11:04:51] WARNING [django.request:144] Not Found: /jqueryCalendar/jquery-ui-1.8.15.custom.min.js
[07/Dec/2015 11:08:49] WARNING [django.request:144] Not Found: /jqueryCalendar/jquery-ui-1.8.15.custom.min.js
[07/Dec/2015 11:08:49] WARNING [django.request:144] Not Found: /jqueryCalendar/jquery-1.6.2.min.js
[07/Dec/2015 11:08:49] WARNING [django.request:144] Not Found: /jqueryCalendar/jqueryCalendar.css
[07/Dec/2015 11:08:54] WARNING [django.request:144] Not Found: /jqueryCalendar/jqueryCalendar.css
[07/Dec/2015 11:08:54] WARNING [django.request:144] Not Found: /jqueryCalendar/jquery-1.6.2.min.js
[07/Dec/2015 11:08:54] WARNING [django.request:144] Not Found: /jqueryCalendar/jquery-ui-1.8.15.custom.min.js
[07/Dec/2015 11:21:06] ERROR [django.request:210] Internal Server Error: /
Traceback (most recent call last):
  File "/home/osboxes/.local/lib/python2.7/site-packages/django/core/handlers/base.py", line 101, in get_response
    resolver_match = resolver.resolve(request.path_info)
  File "/home/osboxes/.local/lib/python2.7/site-packages/django/core/urlresolvers.py", line 338, in resolve
    for pattern in self.url_patterns:
  File "/home/osboxes/.local/lib/python2.7/site-packages/django/core/urlresolvers.py", line 366, in url_patterns
    patterns = getattr(self.urlconf_module, "urlpatterns", self.urlconf_module)
  File "/home/osboxes/.local/lib/python2.7/site-packages/django/core/urlresolvers.py", line 361, in urlconf_module
    self._urlconf_module = import_module(self.urlconf_name)
  File "/home/osboxes/.local/lib/python2.7/site-packages/django/utils/importlib.py", line 35, in import_module
    __import__(name)
  File "/home/osboxes/Desktop/tweetone/tweetone/urls.py", line 3, in <module>
    from tweetexamp import views
  File "/home/osboxes/Desktop/tweetone/tweetexamp/views.py", line 9, in <module>
    print (connection);
NameError: name 'connection' is not defined
[07/Dec/2015 11:21:10] ERROR [django.request:210] Internal Server Error: /favicon.ico
Traceback (most recent call last):
  File "/home/osboxes/.local/lib/python2.7/site-packages/django/core/handlers/base.py", line 90, in get_response
    response = middleware_method(request)
  File "/home/osboxes/.local/lib/python2.7/site-packages/django/middleware/common.py", line 69, in process_request
    if (not urlresolvers.is_valid_path(request.path_info, urlconf) and
  File "/home/osboxes/.local/lib/python2.7/site-packages/django/core/urlresolvers.py", line 577, in is_valid_path
    resolve(path, urlconf)
  File "/home/osboxes/.local/lib/python2.7/site-packages/django/core/urlresolvers.py", line 466, in resolve
    return get_resolver(urlconf).resolve(path)
  File "/home/osboxes/.local/lib/python2.7/site-packages/django/core/urlresolvers.py", line 338, in resolve
    for pattern in self.url_patterns:
  File "/home/osboxes/.local/lib/python2.7/site-packages/django/core/urlresolvers.py", line 366, in url_patterns
    patterns = getattr(self.urlconf_module, "urlpatterns", self.urlconf_module)
  File "/home/osboxes/.local/lib/python2.7/site-packages/django/core/urlresolvers.py", line 361, in urlconf_module
    self._urlconf_module = import_module(self.urlconf_name)
  File "/home/osboxes/.local/lib/python2.7/site-packages/django/utils/importlib.py", line 35, in import_module
    __import__(name)
  File "/home/osboxes/Desktop/tweetone/tweetone/urls.py", line 3, in <module>
    from tweetexamp import views
  File "/home/osboxes/Desktop/tweetone/tweetexamp/views.py", line 9, in <module>
    print (connection);
NameError: name 'connection' is not defined
[07/Dec/2015 11:22:19] ERROR [django.request:210] Internal Server Error: /
Traceback (most recent call last):
  File "/home/osboxes/.local/lib/python2.7/site-packages/django/core/handlers/base.py", line 101, in get_response
    resolver_match = resolver.resolve(request.path_info)
  File "/home/osboxes/.local/lib/python2.7/site-packages/django/core/urlresolvers.py", line 338, in resolve
    for pattern in self.url_patterns:
  File "/home/osboxes/.local/lib/python2.7/site-packages/django/core/urlresolvers.py", line 366, in url_patterns
    patterns = getattr(self.urlconf_module, "urlpatterns", self.urlconf_module)
  File "/home/osboxes/.local/lib/python2.7/site-packages/django/core/urlresolvers.py", line 361, in urlconf_module
    self._urlconf_module = import_module(self.urlconf_name)
  File "/home/osboxes/.local/lib/python2.7/site-packages/django/utils/importlib.py", line 35, in import_module
    __import__(name)
  File "/home/osboxes/Desktop/tweetone/tweetone/urls.py", line 3, in <module>
    from tweetexamp import views
  File "/home/osboxes/Desktop/tweetone/tweetexamp/views.py", line 9, in <module>
    print (connection)
NameError: name 'connection' is not defined
[07/Dec/2015 11:22:19] ERROR [django.request:210] Internal Server Error: /favicon.ico
Traceback (most recent call last):
  File "/home/osboxes/.local/lib/python2.7/site-packages/django/core/handlers/base.py", line 90, in get_response
    response = middleware_method(request)
  File "/home/osboxes/.local/lib/python2.7/site-packages/django/middleware/common.py", line 69, in process_request
    if (not urlresolvers.is_valid_path(request.path_info, urlconf) and
  File "/home/osboxes/.local/lib/python2.7/site-packages/django/core/urlresolvers.py", line 577, in is_valid_path
    resolve(path, urlconf)
  File "/home/osboxes/.local/lib/python2.7/site-packages/django/core/urlresolvers.py", line 466, in resolve
    return get_resolver(urlconf).resolve(path)
  File "/home/osboxes/.local/lib/python2.7/site-packages/django/core/urlresolvers.py", line 338, in resolve
    for pattern in self.url_patterns:
  File "/home/osboxes/.local/lib/python2.7/site-packages/django/core/urlresolvers.py", line 366, in url_patterns
    patterns = getattr(self.urlconf_module, "urlpatterns", self.urlconf_module)
  File "/home/osboxes/.local/lib/python2.7/site-packages/django/core/urlresolvers.py", line 361, in urlconf_module
    self._urlconf_module = import_module(self.urlconf_name)
  File "/home/osboxes/.local/lib/python2.7/site-packages/django/utils/importlib.py", line 35, in import_module
    __import__(name)
  File "/home/osboxes/Desktop/tweetone/tweetone/urls.py", line 3, in <module>
    from tweetexamp import views
  File "/home/osboxes/Desktop/tweetone/tweetexamp/views.py", line 9, in <module>
    print (connection)
NameError: name 'connection' is not defined
[07/Dec/2015 11:22:25] ERROR [django.request:210] Internal Server Error: /
Traceback (most recent call last):
  File "/home/osboxes/.local/lib/python2.7/site-packages/django/core/handlers/base.py", line 101, in get_response
    resolver_match = resolver.resolve(request.path_info)
  File "/home/osboxes/.local/lib/python2.7/site-packages/django/core/urlresolvers.py", line 338, in resolve
    for pattern in self.url_patterns:
  File "/home/osboxes/.local/lib/python2.7/site-packages/django/core/urlresolvers.py", line 366, in url_patterns
    patterns = getattr(self.urlconf_module, "urlpatterns", self.urlconf_module)
  File "/home/osboxes/.local/lib/python2.7/site-packages/django/core/urlresolvers.py", line 361, in urlconf_module
    self._urlconf_module = import_module(self.urlconf_name)
  File "/home/osboxes/.local/lib/python2.7/site-packages/django/utils/importlib.py", line 35, in import_module
    __import__(name)
  File "/home/osboxes/Desktop/tweetone/tweetone/urls.py", line 3, in <module>
    from tweetexamp import views
  File "/home/osboxes/Desktop/tweetone/tweetexamp/views.py", line 9, in <module>
    print (connection)
NameError: name 'connection' is not defined
[07/Dec/2015 11:22:30] ERROR [django.request:210] Internal Server Error: /favicon.ico
Traceback (most recent call last):
  File "/home/osboxes/.local/lib/python2.7/site-packages/django/core/handlers/base.py", line 90, in get_response
    response = middleware_method(request)
  File "/home/osboxes/.local/lib/python2.7/site-packages/django/middleware/common.py", line 69, in process_request
    if (not urlresolvers.is_valid_path(request.path_info, urlconf) and
  File "/home/osboxes/.local/lib/python2.7/site-packages/django/core/urlresolvers.py", line 577, in is_valid_path
    resolve(path, urlconf)
  File "/home/osboxes/.local/lib/python2.7/site-packages/django/core/urlresolvers.py", line 466, in resolve
    return get_resolver(urlconf).resolve(path)
  File "/home/osboxes/.local/lib/python2.7/site-packages/django/core/urlresolvers.py", line 338, in resolve
    for pattern in self.url_patterns:
  File "/home/osboxes/.local/lib/python2.7/site-packages/django/core/urlresolvers.py", line 366, in url_patterns
    patterns = getattr(self.urlconf_module, "urlpatterns", self.urlconf_module)
  File "/home/osboxes/.local/lib/python2.7/site-packages/django/core/urlresolvers.py", line 361, in urlconf_module
    self._urlconf_module = import_module(self.urlconf_name)
  File "/home/osboxes/.local/lib/python2.7/site-packages/django/utils/importlib.py", line 35, in import_module
    __import__(name)
  File "/home/osboxes/Desktop/tweetone/tweetone/urls.py", line 3, in <module>
    from tweetexamp import views
  File "/home/osboxes/Desktop/tweetone/tweetexamp/views.py", line 9, in <module>
    print (connection)
NameError: name 'connection' is not defined
[07/Dec/2015 11:22:58] WARNING [django.request:144] Not Found: /jqueryCalendar/jquery-1.6.2.min.js
[07/Dec/2015 11:22:59] WARNING [django.request:144] Not Found: /jqueryCalendar/jquery-ui-1.8.15.custom.min.js
[07/Dec/2015 11:22:59] WARNING [django.request:144] Not Found: /jqueryCalendar/jqueryCalendar.css
[07/Dec/2015 11:22:59] WARNING [django.request:144] Not Found: /favicon.ico
[07/Dec/2015 11:23:17] WARNING [django.request:144] Not Found: /jqueryCalendar/jquery-1.6.2.min.js
[07/Dec/2015 11:23:17] WARNING [django.request:144] Not Found: /jqueryCalendar/jquery-ui-1.8.15.custom.min.js
[07/Dec/2015 11:23:17] WARNING [django.request:144] Not Found: /jqueryCalendar/jqueryCalendar.css
[07/Dec/2015 11:27:07] ERROR [django.request:210] Internal Server Error: /
Traceback (most recent call last):
  File "/home/osboxes/.local/lib/python2.7/site-packages/django/core/handlers/base.py", line 101, in get_response
    resolver_match = resolver.resolve(request.path_info)
  File "/home/osboxes/.local/lib/python2.7/site-packages/django/core/urlresolvers.py", line 338, in resolve
    for pattern in self.url_patterns:
  File "/home/osboxes/.local/lib/python2.7/site-packages/django/core/urlresolvers.py", line 366, in url_patterns
    patterns = getattr(self.urlconf_module, "urlpatterns", self.urlconf_module)
  File "/home/osboxes/.local/lib/python2.7/site-packages/django/core/urlresolvers.py", line 361, in urlconf_module
    self._urlconf_module = import_module(self.urlconf_name)
  File "/home/osboxes/.local/lib/python2.7/site-packages/django/utils/importlib.py", line 35, in import_module
    __import__(name)
  File "/home/osboxes/Desktop/tweetone/tweetone/urls.py", line 3, in <module>
    from tweetexamp import views
  File "/home/osboxes/Desktop/tweetone/tweetexamp/views.py", line 62
    elif:
       ^
SyntaxError: invalid syntax
[07/Dec/2015 11:28:25] ERROR [django.request:210] Internal Server Error: /
Traceback (most recent call last):
  File "/home/osboxes/.local/lib/python2.7/site-packages/django/core/handlers/base.py", line 101, in get_response
    resolver_match = resolver.resolve(request.path_info)
  File "/home/osboxes/.local/lib/python2.7/site-packages/django/core/urlresolvers.py", line 338, in resolve
    for pattern in self.url_patterns:
  File "/home/osboxes/.local/lib/python2.7/site-packages/django/core/urlresolvers.py", line 366, in url_patterns
    patterns = getattr(self.urlconf_module, "urlpatterns", self.urlconf_module)
  File "/home/osboxes/.local/lib/python2.7/site-packages/django/core/urlresolvers.py", line 361, in urlconf_module
    self._urlconf_module = import_module(self.urlconf_name)
  File "/home/osboxes/.local/lib/python2.7/site-packages/django/utils/importlib.py", line 35, in import_module
    __import__(name)
  File "/home/osboxes/Desktop/tweetone/tweetone/urls.py", line 3, in <module>
    from tweetexamp import views
  File "/home/osboxes/Desktop/tweetone/tweetexamp/views.py", line 26
    if:
      ^
SyntaxError: invalid syntax
[07/Dec/2015 11:28:30] ERROR [django.request:210] Internal Server Error: /
Traceback (most recent call last):
  File "/home/osboxes/.local/lib/python2.7/site-packages/django/core/handlers/base.py", line 101, in get_response
    resolver_match = resolver.resolve(request.path_info)
  File "/home/osboxes/.local/lib/python2.7/site-packages/django/core/urlresolvers.py", line 338, in resolve
    for pattern in self.url_patterns:
  File "/home/osboxes/.local/lib/python2.7/site-packages/django/core/urlresolvers.py", line 366, in url_patterns
    patterns = getattr(self.urlconf_module, "urlpatterns", self.urlconf_module)
  File "/home/osboxes/.local/lib/python2.7/site-packages/django/core/urlresolvers.py", line 361, in urlconf_module
    self._urlconf_module = import_module(self.urlconf_name)
  File "/home/osboxes/.local/lib/python2.7/site-packages/django/utils/importlib.py", line 35, in import_module
    __import__(name)
  File "/home/osboxes/Desktop/tweetone/tweetone/urls.py", line 3, in <module>
    from tweetexamp import views
  File "/home/osboxes/Desktop/tweetone/tweetexamp/views.py", line 26
    if:
      ^
SyntaxError: invalid syntax
[07/Dec/2015 11:28:57] WARNING [django.request:144] Not Found: /jqueryCalendar/jquery-1.6.2.min.js
[07/Dec/2015 11:28:57] WARNING [django.request:144] Not Found: /jqueryCalendar/jquery-ui-1.8.15.custom.min.js
[07/Dec/2015 11:28:57] WARNING [django.request:144] Not Found: /jqueryCalendar/jqueryCalendar.css
[07/Dec/2015 11:47:42] WARNING [django.request:144] Not Found: /jqueryCalendar/jquery-1.6.2.min.js
[07/Dec/2015 11:47:42] WARNING [django.request:144] Not Found: /jqueryCalendar/jquery-ui-1.8.15.custom.min.js
[07/Dec/2015 11:47:42] WARNING [django.request:144] Not Found: /jqueryCalendar/jqueryCalendar.css
[07/Dec/2015 11:48:08] WARNING [django.request:144] Not Found: /jqueryCalendar/jquery-ui-1.8.15.custom.min.js
[07/Dec/2015 11:48:08] WARNING [django.request:144] Not Found: /jqueryCalendar/jquery-1.6.2.min.js
[07/Dec/2015 11:48:08] WARNING [django.request:144] Not Found: /jqueryCalendar/jqueryCalendar.css
[07/Dec/2015 12:59:24] ERROR [django.request:210] Internal Server Error: /
Traceback (most recent call last):
  File "/home/osboxes/.local/lib/python2.7/site-packages/django/core/handlers/base.py", line 113, in get_response
    response = callback(request, *callback_args, **callback_kwargs)
  File "/home/osboxes/Desktop/tweetone/tweetexamp/views.py", line 26, in index
    return render(request, 'index.html')
  File "/home/osboxes/.local/lib/python2.7/site-packages/django/shortcuts/__init__.py", line 53, in render
    return HttpResponse(loader.render_to_string(*args, **kwargs),
  File "/home/osboxes/.local/lib/python2.7/site-packages/django/template/loader.py", line 170, in render_to_string
    t = get_template(template_name)
  File "/home/osboxes/.local/lib/python2.7/site-packages/django/template/loader.py", line 146, in get_template
    template, origin = find_template(template_name)
  File "/home/osboxes/.local/lib/python2.7/site-packages/django/template/loader.py", line 135, in find_template
    source, display_name = loader(name, dirs)
  File "/home/osboxes/.local/lib/python2.7/site-packages/django/template/loader.py", line 43, in __call__
    return self.load_template(template_name, template_dirs)
  File "/home/osboxes/.local/lib/python2.7/site-packages/django/template/loader.py", line 49, in load_template
    template = get_template_from_string(source, origin, template_name)
  File "/home/osboxes/.local/lib/python2.7/site-packages/django/template/loader.py", line 157, in get_template_from_string
    return Template(source, origin, name)
  File "/home/osboxes/.local/lib/python2.7/site-packages/django/template/base.py", line 125, in __init__
    self.nodelist = compile_string(template_string, origin)
  File "/home/osboxes/.local/lib/python2.7/site-packages/django/template/base.py", line 153, in compile_string
    return parser.parse()
  File "/home/osboxes/.local/lib/python2.7/site-packages/django/template/base.py", line 274, in parse
    compiled_result = compile_func(self, token)
  File "/home/osboxes/.local/lib/python2.7/site-packages/django/template/defaulttags.py", line 769, in do_for
    nodelist_loop = parser.parse(('empty', 'endfor',))
  File "/home/osboxes/.local/lib/python2.7/site-packages/django/template/base.py", line 274, in parse
    compiled_result = compile_func(self, token)
  File "/home/osboxes/.local/lib/python2.7/site-packages/django/template/defaulttags.py", line 1290, in url
    args.append(parser.compile_filter(value))
  File "/home/osboxes/.local/lib/python2.7/site-packages/django/template/base.py", line 353, in compile_filter
    return FilterExpression(token, self)
  File "/home/osboxes/.local/lib/python2.7/site-packages/django/template/base.py", line 564, in __init__
    filter_func = parser.find_filter(filter_name)
  File "/home/osboxes/.local/lib/python2.7/site-packages/django/template/base.py", line 359, in find_filter
    raise TemplateSyntaxError("Invalid filter: '%s'" % filter_name)
TemplateSyntaxError: Invalid filter: 'mongo_id'
[07/Dec/2015 13:00:56] WARNING [django.request:144] Not Found: /World.jpg
[07/Dec/2015 13:32:10] ERROR [django.request:210] Internal Server Error: /
Traceback (most recent call last):
  File "/home/osboxes/.local/lib/python2.7/site-packages/django/core/handlers/base.py", line 113, in get_response
    response = callback(request, *callback_args, **callback_kwargs)
  File "/home/osboxes/Desktop/tweetone/tweetexamp/views.py", line 26, in index
    return render(request, 'index.html')
  File "/home/osboxes/.local/lib/python2.7/site-packages/django/shortcuts/__init__.py", line 53, in render
    return HttpResponse(loader.render_to_string(*args, **kwargs),
  File "/home/osboxes/.local/lib/python2.7/site-packages/django/template/loader.py", line 170, in render_to_string
    t = get_template(template_name)
  File "/home/osboxes/.local/lib/python2.7/site-packages/django/template/loader.py", line 146, in get_template
    template, origin = find_template(template_name)
  File "/home/osboxes/.local/lib/python2.7/site-packages/django/template/loader.py", line 135, in find_template
    source, display_name = loader(name, dirs)
  File "/home/osboxes/.local/lib/python2.7/site-packages/django/template/loader.py", line 43, in __call__
    return self.load_template(template_name, template_dirs)
  File "/home/osboxes/.local/lib/python2.7/site-packages/django/template/loader.py", line 49, in load_template
    template = get_template_from_string(source, origin, template_name)
  File "/home/osboxes/.local/lib/python2.7/site-packages/django/template/loader.py", line 157, in get_template_from_string
    return Template(source, origin, name)
  File "/home/osboxes/.local/lib/python2.7/site-packages/django/template/base.py", line 125, in __init__
    self.nodelist = compile_string(template_string, origin)
  File "/home/osboxes/.local/lib/python2.7/site-packages/django/template/base.py", line 153, in compile_string
    return parser.parse()
  File "/home/osboxes/.local/lib/python2.7/site-packages/django/template/base.py", line 274, in parse
    compiled_result = compile_func(self, token)
  File "/home/osboxes/.local/lib/python2.7/site-packages/django/template/defaulttags.py", line 769, in do_for
    nodelist_loop = parser.parse(('empty', 'endfor',))
  File "/home/osboxes/.local/lib/python2.7/site-packages/django/template/base.py", line 274, in parse
    compiled_result = compile_func(self, token)
  File "/home/osboxes/.local/lib/python2.7/site-packages/django/template/defaulttags.py", line 1290, in url
    args.append(parser.compile_filter(value))
  File "/home/osboxes/.local/lib/python2.7/site-packages/django/template/base.py", line 353, in compile_filter
    return FilterExpression(token, self)
  File "/home/osboxes/.local/lib/python2.7/site-packages/django/template/base.py", line 564, in __init__
    filter_func = parser.find_filter(filter_name)
  File "/home/osboxes/.local/lib/python2.7/site-packages/django/template/base.py", line 359, in find_filter
    raise TemplateSyntaxError("Invalid filter: '%s'" % filter_name)
TemplateSyntaxError: Invalid filter: 'mongo_id'
[07/Dec/2015 16:03:23] ERROR [django.request:210] Internal Server Error: /search/scs/
Traceback (most recent call last):
  File "/home/osboxes/.local/lib/python2.7/site-packages/django/core/handlers/base.py", line 113, in get_response
    response = callback(request, *callback_args, **callback_kwargs)
  File "/home/osboxes/Desktop/tweetone/tweetexamp/views.py", line 74, in comments
    item = tweets.find({'_id': ObjectId(id) })
  File "/usr/local/lib/python2.7/dist-packages/pymongo-3.2.0.dev0-py2.7-linux-x86_64.egg/bson/objectid.py", line 110, in __init__
    self.__validate(oid)
  File "/usr/local/lib/python2.7/dist-packages/pymongo-3.2.0.dev0-py2.7-linux-x86_64.egg/bson/objectid.py", line 206, in __validate
    _raise_invalid_id(oid)
  File "/usr/local/lib/python2.7/dist-packages/pymongo-3.2.0.dev0-py2.7-linux-x86_64.egg/bson/objectid.py", line 52, in _raise_invalid_id
    " or a 24-character hex string" % oid)
InvalidId: u'scs' is not a valid ObjectId, it must be a 12-byte input or a 24-character hex string
[07/Dec/2015 17:19:42] WARNING [django.request:144] Not Found: /favicon.ico
[07/Dec/2015 17:38:57] ERROR [django.request:210] Internal Server Error: /search/scs/
Traceback (most recent call last):
  File "/home/osboxes/.local/lib/python2.7/site-packages/django/core/handlers/base.py", line 113, in get_response
    response = callback(request, *callback_args, **callback_kwargs)
  File "/home/osboxes/Desktop/tweetone/tweetexamp/views.py", line 74, in comments
    item = tweets.find({'_id': ObjectId(id) })
  File "/usr/local/lib/python2.7/dist-packages/pymongo-3.2.0.dev0-py2.7-linux-x86_64.egg/bson/objectid.py", line 110, in __init__
    self.__validate(oid)
  File "/usr/local/lib/python2.7/dist-packages/pymongo-3.2.0.dev0-py2.7-linux-x86_64.egg/bson/objectid.py", line 206, in __validate
    _raise_invalid_id(oid)
  File "/usr/local/lib/python2.7/dist-packages/pymongo-3.2.0.dev0-py2.7-linux-x86_64.egg/bson/objectid.py", line 52, in _raise_invalid_id
    " or a 24-character hex string" % oid)
InvalidId: u'scs' is not a valid ObjectId, it must be a 12-byte input or a 24-character hex string
[07/Dec/2015 17:50:50] ERROR [django.request:210] Internal Server Error: /
Traceback (most recent call last):
  File "/home/osboxes/.local/lib/python2.7/site-packages/django/core/handlers/base.py", line 101, in get_response
    resolver_match = resolver.resolve(request.path_info)
  File "/home/osboxes/.local/lib/python2.7/site-packages/django/core/urlresolvers.py", line 338, in resolve
    for pattern in self.url_patterns:
  File "/home/osboxes/.local/lib/python2.7/site-packages/django/core/urlresolvers.py", line 366, in url_patterns
    patterns = getattr(self.urlconf_module, "urlpatterns", self.urlconf_module)
  File "/home/osboxes/.local/lib/python2.7/site-packages/django/core/urlresolvers.py", line 361, in urlconf_module
    self._urlconf_module = import_module(self.urlconf_name)
  File "/home/osboxes/.local/lib/python2.7/site-packages/django/utils/importlib.py", line 35, in import_module
    __import__(name)
  File "/home/osboxes/Desktop/tweetone/tweetone/urls.py", line 9
    url(r'^$', views.index, name='index'),
      ^
SyntaxError: invalid syntax
[07/Dec/2015 17:51:05] ERROR [django.request:210] Internal Server Error: /
Traceback (most recent call last):
  File "/home/osboxes/.local/lib/python2.7/site-packages/django/core/handlers/base.py", line 101, in get_response
    resolver_match = resolver.resolve(request.path_info)
  File "/home/osboxes/.local/lib/python2.7/site-packages/django/core/urlresolvers.py", line 338, in resolve
    for pattern in self.url_patterns:
  File "/home/osboxes/.local/lib/python2.7/site-packages/django/core/urlresolvers.py", line 366, in url_patterns
    patterns = getattr(self.urlconf_module, "urlpatterns", self.urlconf_module)
  File "/home/osboxes/.local/lib/python2.7/site-packages/django/core/urlresolvers.py", line 361, in urlconf_module
    self._urlconf_module = import_module(self.urlconf_name)
  File "/home/osboxes/.local/lib/python2.7/site-packages/django/utils/importlib.py", line 35, in import_module
    __import__(name)
  File "/home/osboxes/Desktop/tweetone/tweetone/urls.py", line 8, in <module>
    url(r'^$', views.main, name='main'),
AttributeError: 'module' object has no attribute 'main'
[07/Dec/2015 17:52:37] WARNING [django.request:144] Not Found: /travel_03.jpg
[07/Dec/2015 17:52:46] WARNING [django.request:144] Not Found: /index.html
[07/Dec/2015 18:03:16] WARNING [django.request:144] Not Found: /travel_03.jpg
[07/Dec/2015 18:03:18] WARNING [django.request:144] Not Found: /index.html
[07/Dec/2015 18:05:40] WARNING [django.request:144] Not Found: /travel_03.jpg
[07/Dec/2015 18:05:41] WARNING [django.request:144] Not Found: /index.html
[07/Dec/2015 18:06:06] WARNING [django.request:144] Not Found: /travel_03.jpg
[07/Dec/2015 18:06:07] WARNING [django.request:144] Not Found: /index.html
[07/Dec/2015 18:37:06] WARNING [django.request:144] Not Found: /travel_03.jpg
[07/Dec/2015 18:37:08] WARNING [django.request:144] Not Found: /index.html
[07/Dec/2015 18:37:32] ERROR [django.request:210] Internal Server Error: /travel_03.jpg
Traceback (most recent call last):
  File "/home/osboxes/.local/lib/python2.7/site-packages/django/core/handlers/base.py", line 131, in get_response
    raise ValueError("The view %s.%s didn't return an HttpResponse object." % (callback.__module__, view_name))
ValueError: The view tweetexamp.views.search didn't return an HttpResponse object.
[07/Dec/2015 18:37:34] ERROR [django.request:210] Internal Server Error: /index.html
Traceback (most recent call last):
  File "/home/osboxes/.local/lib/python2.7/site-packages/django/core/handlers/base.py", line 131, in get_response
    raise ValueError("The view %s.%s didn't return an HttpResponse object." % (callback.__module__, view_name))
ValueError: The view tweetexamp.views.search didn't return an HttpResponse object.
[07/Dec/2015 18:39:18] ERROR [django.request:210] Internal Server Error: /search
Traceback (most recent call last):
  File "/home/osboxes/.local/lib/python2.7/site-packages/django/core/handlers/base.py", line 131, in get_response
    raise ValueError("The view %s.%s didn't return an HttpResponse object." % (callback.__module__, view_name))
ValueError: The view tweetexamp.views.search didn't return an HttpResponse object.
[07/Dec/2015 18:46:29] WARNING [django.request:144] Not Found: /travel_03.jpg
[07/Dec/2015 18:46:30] WARNING [django.request:144] Not Found: /favicon.ico
[07/Dec/2015 18:46:33] WARNING [django.request:144] Not Found: /index.html
[07/Dec/2015 18:47:43] WARNING [django.request:144] Not Found: /travel_03.jpg
[07/Dec/2015 18:47:46] WARNING [django.request:144] Not Found: /index.html
[07/Dec/2015 18:48:26] WARNING [django.request:144] Not Found: /travel_03.jpg
[07/Dec/2015 18:48:28] WARNING [django.request:144] Not Found: /index.html
[07/Dec/2015 18:48:45] WARNING [django.request:144] Not Found: /travel_03.jpg
[07/Dec/2015 18:48:46] WARNING [django.request:144] Not Found: /index.html
[07/Dec/2015 19:00:27] WARNING [django.request:144] Not Found: /travel_03.jpg
[07/Dec/2015 19:00:38] WARNING [django.request:144] Not Found: /index.html
[07/Dec/2015 19:07:42] WARNING [django.request:144] Not Found: /travel_03.jpg
[07/Dec/2015 19:07:43] WARNING [django.request:144] Not Found: /index.html
[07/Dec/2015 19:08:06] ERROR [django.request:210] Internal Server Error: /travel_03.jpg
Traceback (most recent call last):
  File "/home/osboxes/.local/lib/python2.7/site-packages/django/core/handlers/base.py", line 90, in get_response
    response = middleware_method(request)
  File "/home/osboxes/.local/lib/python2.7/site-packages/django/middleware/common.py", line 69, in process_request
    if (not urlresolvers.is_valid_path(request.path_info, urlconf) and
  File "/home/osboxes/.local/lib/python2.7/site-packages/django/core/urlresolvers.py", line 577, in is_valid_path
    resolve(path, urlconf)
  File "/home/osboxes/.local/lib/python2.7/site-packages/django/core/urlresolvers.py", line 466, in resolve
    return get_resolver(urlconf).resolve(path)
  File "/home/osboxes/.local/lib/python2.7/site-packages/django/core/urlresolvers.py", line 340, in resolve
    sub_match = pattern.resolve(new_path)
  File "/home/osboxes/.local/lib/python2.7/site-packages/django/core/urlresolvers.py", line 211, in resolve
    match = self.regex.search(path)
  File "/home/osboxes/.local/lib/python2.7/site-packages/django/core/urlresolvers.py", line 179, in regex
    (regex, six.text_type(e)))
ImproperlyConfigured: "^[a-zA-Z0-9]+)" is not a valid regular expression: unbalanced parenthesis
[07/Dec/2015 19:08:08] ERROR [django.request:210] Internal Server Error: /index.html
Traceback (most recent call last):
  File "/home/osboxes/.local/lib/python2.7/site-packages/django/core/handlers/base.py", line 90, in get_response
    response = middleware_method(request)
  File "/home/osboxes/.local/lib/python2.7/site-packages/django/middleware/common.py", line 69, in process_request
    if (not urlresolvers.is_valid_path(request.path_info, urlconf) and
  File "/home/osboxes/.local/lib/python2.7/site-packages/django/core/urlresolvers.py", line 577, in is_valid_path
    resolve(path, urlconf)
  File "/home/osboxes/.local/lib/python2.7/site-packages/django/core/urlresolvers.py", line 466, in resolve
    return get_resolver(urlconf).resolve(path)
  File "/home/osboxes/.local/lib/python2.7/site-packages/django/core/urlresolvers.py", line 340, in resolve
    sub_match = pattern.resolve(new_path)
  File "/home/osboxes/.local/lib/python2.7/site-packages/django/core/urlresolvers.py", line 211, in resolve
    match = self.regex.search(path)
  File "/home/osboxes/.local/lib/python2.7/site-packages/django/core/urlresolvers.py", line 179, in regex
    (regex, six.text_type(e)))
ImproperlyConfigured: "^[a-zA-Z0-9]+)" is not a valid regular expression: unbalanced parenthesis
[07/Dec/2015 19:16:46] ERROR [django.request:210] Internal Server Error: /
Traceback (most recent call last):
  File "/home/osboxes/.local/lib/python2.7/site-packages/django/core/handlers/base.py", line 113, in get_response
    response = callback(request, *callback_args, **callback_kwargs)
  File "/home/osboxes/Desktop/tweetone/tweetexamp/views.py", line 25, in main
    return render(request, 'main.html')
  File "/home/osboxes/.local/lib/python2.7/site-packages/django/shortcuts/__init__.py", line 53, in render
    return HttpResponse(loader.render_to_string(*args, **kwargs),
  File "/home/osboxes/.local/lib/python2.7/site-packages/django/template/loader.py", line 170, in render_to_string
    t = get_template(template_name)
  File "/home/osboxes/.local/lib/python2.7/site-packages/django/template/loader.py", line 146, in get_template
    template, origin = find_template(template_name)
  File "/home/osboxes/.local/lib/python2.7/site-packages/django/template/loader.py", line 135, in find_template
    source, display_name = loader(name, dirs)
  File "/home/osboxes/.local/lib/python2.7/site-packages/django/template/loader.py", line 43, in __call__
    return self.load_template(template_name, template_dirs)
  File "/home/osboxes/.local/lib/python2.7/site-packages/django/template/loader.py", line 49, in load_template
    template = get_template_from_string(source, origin, template_name)
  File "/home/osboxes/.local/lib/python2.7/site-packages/django/template/loader.py", line 157, in get_template_from_string
    return Template(source, origin, name)
  File "/home/osboxes/.local/lib/python2.7/site-packages/django/template/base.py", line 125, in __init__
    self.nodelist = compile_string(template_string, origin)
  File "/home/osboxes/.local/lib/python2.7/site-packages/django/template/base.py", line 153, in compile_string
    return parser.parse()
  File "/home/osboxes/.local/lib/python2.7/site-packages/django/template/base.py", line 274, in parse
    compiled_result = compile_func(self, token)
  File "/home/osboxes/.local/lib/python2.7/site-packages/django/template/defaulttags.py", line 1290, in url
    args.append(parser.compile_filter(value))
  File "/home/osboxes/.local/lib/python2.7/site-packages/django/template/base.py", line 353, in compile_filter
    return FilterExpression(token, self)
  File "/home/osboxes/.local/lib/python2.7/site-packages/django/template/base.py", line 564, in __init__
    filter_func = parser.find_filter(filter_name)
  File "/home/osboxes/.local/lib/python2.7/site-packages/django/template/base.py", line 359, in find_filter
    raise TemplateSyntaxError("Invalid filter: '%s'" % filter_name)
TemplateSyntaxError: Invalid filter: 'mongo_id'
[07/Dec/2015 19:25:31] ERROR [django.request:210] Internal Server Error: /
Traceback (most recent call last):
  File "/home/osboxes/.local/lib/python2.7/site-packages/django/core/handlers/base.py", line 113, in get_response
    response = callback(request, *callback_args, **callback_kwargs)
  File "/home/osboxes/Desktop/tweetone/tweetexamp/views.py", line 25, in main
    return render(request, 'main.html')
  File "/home/osboxes/.local/lib/python2.7/site-packages/django/shortcuts/__init__.py", line 53, in render
    return HttpResponse(loader.render_to_string(*args, **kwargs),
  File "/home/osboxes/.local/lib/python2.7/site-packages/django/template/loader.py", line 177, in render_to_string
    return t.render(context_instance)
  File "/home/osboxes/.local/lib/python2.7/site-packages/django/template/base.py", line 140, in render
    return self._render(context)
  File "/home/osboxes/.local/lib/python2.7/site-packages/django/template/base.py", line 134, in _render
    return self.nodelist.render(context)
  File "/home/osboxes/.local/lib/python2.7/site-packages/django/template/base.py", line 830, in render
    bit = self.render_node(node, context)
  File "/home/osboxes/.local/lib/python2.7/site-packages/django/template/debug.py", line 74, in render_node
    return node.render(context)
  File "/home/osboxes/.local/lib/python2.7/site-packages/django/template/defaulttags.py", line 426, in render
    raise e
NoReverseMatch: Reverse for 'index' with arguments '(u'index',)' and keyword arguments '{}' not found.
[07/Dec/2015 19:26:05] WARNING [django.request:144] Not Found: /travel_03.jpg
[07/Dec/2015 19:27:14] WARNING [django.request:144] Not Found: /travel_03.jpg
[07/Dec/2015 19:35:13] WARNING [django.request:144] Not Found: /travel_03.jpg
[07/Dec/2015 19:35:13] WARNING [django.request:144] Not Found: /favicon.ico
[07/Dec/2015 19:36:47] WARNING [django.request:144] Not Found: /travel_03.jpg
[07/Dec/2015 19:36:51] WARNING [django.request:144] Not Found: /travel_03.jpg
[07/Dec/2015 19:36:57] WARNING [django.request:144] Not Found: /travel_03.jpg
[07/Dec/2015 19:44:24] INFO [django.db.backends:21] Mongodb connected
[07/Dec/2015 19:44:24] ERROR [django.request:210] Internal Server Error: /
Traceback (most recent call last):
  File "/home/osboxes/.local/lib/python2.7/site-packages/django/core/handlers/base.py", line 101, in get_response
    resolver_match = resolver.resolve(request.path_info)
  File "/home/osboxes/.local/lib/python2.7/site-packages/django/core/urlresolvers.py", line 338, in resolve
    for pattern in self.url_patterns:
  File "/home/osboxes/.local/lib/python2.7/site-packages/django/core/urlresolvers.py", line 366, in url_patterns
    patterns = getattr(self.urlconf_module, "urlpatterns", self.urlconf_module)
  File "/home/osboxes/.local/lib/python2.7/site-packages/django/core/urlresolvers.py", line 361, in urlconf_module
    self._urlconf_module = import_module(self.urlconf_name)
  File "/home/osboxes/.local/lib/python2.7/site-packages/django/utils/importlib.py", line 35, in import_module
    __import__(name)
  File "/home/osboxes/Desktop/tweetone/tweetone/urls.py", line 8, in <module>
    url(r'^$', views.main, name='main'),
AttributeError: 'module' object has no attribute 'main'
